<?xml version="1.0" ?>
<!-- =================================================================================== -->
<!-- |    This document was autogenerated by xacro from /home/bing6866/桌面/work/松灵机器人/work1/重置版/ros2_ws/src/tracer_description/urdf/tracer_v1.xacro | -->
<!-- |    EDITING THIS FILE BY HAND IS NOT RECOMMENDED                                 | -->
<!-- =================================================================================== -->
<robot name="tracer_v1">
  <!--0.37810-->
  <!--    <xacro:property name="track" value="0.3426" />
    <xacro:property name="wheelbase" value="0.3181"/>
    <xacro:property name="wheel_vertical_offset" value="-0.160000047342231" />-->
  <!-- Base link -->
  <link name="base_link">
    <visual>
      <origin rpy="1.57 0 0" xyz="0 0 0"/>
      <!--<origin xyz="0 0 0" rpy="0 0 0"/>-->
      <geometry>
        <mesh filename="file:///home/bing6866/桌面/work/松灵机器人/work1/重置版/ros2_ws/install/tracer_description/share/tracer_description/meshes/tracer_base_link_no_wheel.dae"/>
        <!--<box size="${base_x_size} ${base_y_size} ${base_z_size}"/>-->
      </geometry>
    </visual>
    <collision>
      <!--origin
            xyz="-0.0145261552504705 0.0231316650320557 0.00586280190939592"
            rpy="0 0 0" /-->
      <origin rpy="1.57 0 0" xyz="0 0 0"/>
      <geometry>
        <mesh filename="file:///home/bing6866/桌面/work/松灵机器人/work1/重置版/ros2_ws/install/tracer_description/share/tracer_description/meshes/tracer_base_link_no_wheel.dae"/>
        <!--<box size="${base_x_size} ${base_y_size} ${base_z_size}"/>-->
      </geometry>
    </collision>
  </link>
  <!-- <joint name="chassis_link_joint" type="fixed">
        <origin xyz="0 0 ${wheel_radius - wheel_vertical_offset}" rpy="0 0 0" />
        <parent link="base_link" />
        <child link="chassis_link" />
    </joint> -->
  <link name="inertial_link">
    <inertial>
      <!--mass value="44.3898489950015" /-->
      <mass value="132.3898489950015"/>
      <!-- <mass value="50" /> -->
      <!-- <origin xyz="-0.00065 -0.085 0.062" />
            <inertia ixx="0.6022" ixy="-0.02364" ixz="-0.1197" iyy="1.7386" iyz="-0.001544" izz="2.0296" /> -->
      <origin xyz="0.015 0.0231316650320557 0"/>
      <!--<origin
              xyz="-0.0145261552504705 0.0231316650320557 0.00586280190939592"
              rpy="0 0 0" />-->
      <inertia ixx="0.185196122711036" ixy="4.30144213829512E-08" ixz="5.81037523686401E-08" iyy="0.364893736238929" iyz="-0.000386720198091934" izz="0.223868521722778"/>
      <!--<inertia ixx="2.288641" ixy="0" ixz="0" iyy="5.103976" iyz="0" izz="3.431465" />-->
    </inertial>
  </link>
  <joint name="inertial_joint" type="fixed">
    <origin rpy="0 0 0" xyz="0 0 0"/>
    <parent link="base_link"/>
    <child link="inertial_link"/>
  </joint>
  <!-- For testing, hang the robot up in the air -->
  <!-- <link name="world" />
    <joint name="world_to_base_link=" type="fixed">
        <origin xyz="0 0 0.5" rpy="0 0 0" />
        <parent link="world"/>
        <child link="base_link"/>
    </joint> -->
  <link name="right_wheel_link">
    <!--<inertial>
                <mass value="3" />
                <origin
                        xyz="0.162297526351145 -0.159063056237197 -0.159999952657767"
                        rpy="0 0 0" />
                        <inertia ixx="0.7171" ixy="0" ixz="0" iyy="0.1361" iyz="0" izz="0.7171" />
                   </inertial>
            <visual>
                <origin xyz="0 0 0" rpy="0 0 0" />
                <geometry>
                    <mesh filename="file://$(find tracer_description)/meshes/wheel.dae" />
                </geometry>
            </visual>-->
    <inertial>
      <mass value="6"/>
      <origin xyz="0 0 0"/>
      <inertia ixx="0.7171" ixy="0" ixz="0" iyy="0.1361" iyz="0" izz="0.7171"/>
      <!--<inertia ixx="0" ixy="0" ixz="0" iyy="0" iyz="0" izz="0" />-->
    </inertial>
    <visual>
      <origin rpy="0 0 0" xyz="0 0 0"/>
      <geometry>
        <mesh filename="file:///home/bing6866/桌面/work/松灵机器人/work1/重置版/ros2_ws/install/tracer_description/share/tracer_description/meshes/tracer_wheel.dae"/>
        <!--<cylinder length="0.0787019" radius="0.0457774"/>-->
      </geometry>
    </visual>
    <collision>
      <origin rpy="0 0 0" xyz="0 0 0"/>
      <geometry>
        <mesh filename="file:///home/bing6866/桌面/work/松灵机器人/work1/重置版/ros2_ws/install/tracer_description/share/tracer_description/meshes/tracer_wheel.dae"/>
        <!--<cylinder length="0.0787019" radius="0.0457774"/>-->
      </geometry>
    </collision>
  </link>
  <joint name="right_wheel" type="continuous">
    <!--<origin
                  xyz="0.14547 0.20835 -0.07424"
                  rpy="0 1.57 0" />-->
    <parent link="base_link"/>
    <child link="right_wheel_link"/>
    <origin rpy="0 0 0" xyz="0 -0.17 -0.082"/>
    <axis rpy="0 0 0" xyz="0 1 0"/>
  </joint>
  <link name="left_wheel_link">
    <!--<inertial>
            <mass value="3" />
                <origin
                        xyz="0.162297526351148 0.159063056237198 -0.160000047342231"
                        rpy="0 0 0" />
                        <inertia ixx="0.7171" ixy="0" ixz="0" iyy="0.1361" iyz="0" izz="0.7171" />
            </inertial>
            <visual>
                <origin xyz="0 0 0" rpy="0 0 0" />
                <geometry>
                    <mesh filename="file://$(find tracer_description)/meshes/wheel.dae" />
                </geometry>
            </visual>-->
    <inertial>
      <mass value="6"/>
      <origin xyz="0 0 0"/>
      <inertia ixx="0.7171" ixy="0" ixz="0" iyy="0.1361" iyz="0" izz="0.7171"/>
      <!--<inertia ixx="0" ixy="0" ixz="0" iyy="0" iyz="0" izz="0" />-->
    </inertial>
    <visual>
      <origin rpy="0 0 0" xyz="0 0 0"/>
      <geometry>
        <mesh filename="file:///home/bing6866/桌面/work/松灵机器人/work1/重置版/ros2_ws/install/tracer_description/share/tracer_description/meshes/tracer_wheel.dae"/>
        <!--<cylinder length="0.0787019" radius="0.0457774"/>-->
      </geometry>
    </visual>
    <collision>
      <origin rpy="0 0 0" xyz="0 0 0"/>
      <geometry>
        <mesh filename="file:///home/bing6866/桌面/work/松灵机器人/work1/重置版/ros2_ws/install/tracer_description/share/tracer_description/meshes/tracer_wheel.dae"/>
        <!--<cylinder length="0.0787019" radius="0.0457774"/>-->
      </geometry>
    </collision>
  </link>
  <joint name="left_wheel" type="continuous">
    <!--<origin
                  xyz="-0.17453 0.20835 -0.07424"
                  rpy="0 -1.57 0" />-->
    <parent link="base_link"/>
    <child link="left_wheel_link"/>
    <origin rpy="3.14 0 0" xyz="0 0.17 -0.082"/>
    <axis rpy="0 0 0" xyz="0 -1 0"/>
  </joint>
  <!--tracer castor wheel-->
  <link name="fl_castor_link">
    <inertial>
      <mass value="1"/>
      <origin xyz="0 0 0"/>
      <inertia ixx="0.7171" ixy="0" ixz="0" iyy="0.1361" iyz="0" izz="0.7171"/>
    </inertial>
    <visual>
      <geometry>
        <!--<cylinder length="${castor_length}" radius="${castor_radius}"/>-->
        <mesh filename="file:///home/bing6866/桌面/work/松灵机器人/work1/重置版/ros2_ws/install/tracer_description/share/tracer_description/meshes/castor_joint.dae"/>
      </geometry>
      <!--<material name="black">
                        <color rgba="255 255 255 1"/>
                   </material>-->
    </visual>
    <!--<collision>
              <origin
                xyz="0 0 0"
                rpy="0 0 0" />
              <geometry>
                <cylinder length="${castor_length}" radius="${castor_radius}"/>
                <mesh filename="package://tracer_description/meshes/castor_joint.dae" />
              </geometry>
            </collision>-->
  </link>
  <joint name="fl_castor_wheel" type="continuous">
    <origin rpy="-1.57 0 0" xyz="0.18955 0.17 -0.0380886"/>
    <parent link="base_link"/>
    <child link="fl_castor_link"/>
    <axis rpy="0 0 0" xyz="0 1 0"/>
  </joint>
  <link name="fr_castor_link">
    <inertial>
      <mass value="1"/>
      <origin xyz="0 0 0"/>
      <inertia ixx="0.7171" ixy="0" ixz="0" iyy="0.1361" iyz="0" izz="0.7171"/>
    </inertial>
    <visual>
      <geometry>
        <!--<cylinder length="${castor_length}" radius="${castor_radius}"/>-->
        <mesh filename="file:///home/bing6866/桌面/work/松灵机器人/work1/重置版/ros2_ws/install/tracer_description/share/tracer_description/meshes/castor_joint.dae"/>
      </geometry>
      <!--<material name="black">
                        <color rgba="255 255 255 1"/>
                   </material>-->
    </visual>
    <!--<collision>
              <origin
                xyz="0 0 0"
                rpy="0 0 0" />
              <geometry>
                <cylinder length="${castor_length}" radius="${castor_radius}"/>
                <mesh filename="package://tracer_description/meshes/castor_joint.dae" />
              </geometry>
            </collision>-->
  </link>
  <joint name="fr_castor_wheel" type="continuous">
    <origin rpy="-1.57 0 0" xyz="0.18955 -0.17 -0.0380886"/>
    <parent link="base_link"/>
    <child link="fr_castor_link"/>
    <axis rpy="0 0 0" xyz="0 1 0"/>
  </joint>
  <link name="rr_castor_link">
    <inertial>
      <mass value="1"/>
      <origin xyz="0 0 0"/>
      <inertia ixx="0.7171" ixy="0" ixz="0" iyy="0.1361" iyz="0" izz="0.7171"/>
    </inertial>
    <visual>
      <geometry>
        <!--<cylinder length="${castor_length}" radius="${castor_radius}"/>-->
        <mesh filename="file:///home/bing6866/桌面/work/松灵机器人/work1/重置版/ros2_ws/install/tracer_description/share/tracer_description/meshes/castor_joint.dae"/>
      </geometry>
      <!-- <material name="black">
                        <color rgba="255 255 255 1"/>
                   </material>-->
    </visual>
    <!--<collision>
              <origin
                xyz="0 0 0"
                rpy="0 0 0" />
              <geometry>
                <cylinder length="${castor_length}" radius="${castor_radius}"/>
                <mesh filename="package://tracer_description/meshes/castor_joint.dae" />
              </geometry>
            </collision>-->
  </link>
  <joint name="rr_castor_wheel" type="continuous">
    <origin rpy="-1.57 0 0" xyz="-0.18955 -0.17 -0.0380886"/>
    <parent link="base_link"/>
    <child link="rr_castor_link"/>
    <axis rpy="0 0 0" xyz="0 1 0"/>
  </joint>
  <link name="rl_castor_link">
    <inertial>
      <mass value="1"/>
      <origin xyz="0 0 0"/>
      <inertia ixx="0.7171" ixy="0" ixz="0" iyy="0.1361" iyz="0" izz="0.7171"/>
    </inertial>
    <visual>
      <geometry>
        <!--<cylinder length="${castor_length}" radius="${castor_radius}"/>-->
        <mesh filename="file:///home/bing6866/桌面/work/松灵机器人/work1/重置版/ros2_ws/install/tracer_description/share/tracer_description/meshes/castor_joint.dae"/>
      </geometry>
      <!--<material name="black">
                        <color rgba="255 255 255 1"/>
                   </material>-->
    </visual>
    <!-- <collision>
              <origin
                xyz="0 0 0"
                rpy="0 0 0" />
              <geometry>
                <cylinder length="${castor_length}" radius="${castor_radius}"/>
                <mesh filename="package://tracer_description/meshes/castor_joint.dae" />
              </geometry>
            </collision>-->
  </link>
  <joint name="rl_castor_wheel" type="continuous">
    <origin rpy="-1.57 0 0" xyz="-0.18955 0.17 -0.0380886"/>
    <parent link="base_link"/>
    <child link="rl_castor_link"/>
    <axis rpy="0 0 0" xyz="0 1 0"/>
  </joint>
  <link name="fl_wheel_link">
    <inertial>
      <mass value="1"/>
      <origin xyz="0 0 0"/>
      <inertia ixx="0.3131" ixy="0" ixz="0" iyy="0.3131" iyz="0" izz="0.1361"/>
      <!--<inertia ixx="0" ixy="0" ixz="0" iyy="0" iyz="0" izz="0" />-->
    </inertial>
    <visual>
      <geometry>
        <!--<cylinder length="0.04653" radius="0.036"/>-->
        <!--<sphere radius="0.0457774"/>-->
        <mesh filename="file:///home/bing6866/桌面/work/松灵机器人/work1/重置版/ros2_ws/install/tracer_description/share/tracer_description/meshes/castor.dae"/>
      </geometry>
      <!--<material name="black">
                    <color rgba="255 255 255 1"/>
               </material>-->
    </visual>
    <collision>
      <origin rpy="0 0 0" xyz="0 0 0"/>
      <geometry>
        <!--<cylinder length="0.04653" radius="0.036"/>-->
        <!--<cylinder length="0.0787019" radius="0.0457774"/>-->
        <!--<sphere radius="0.0457774"/>-->
        <mesh filename="file:///home/bing6866/桌面/work/松灵机器人/work1/重置版/ros2_ws/install/tracer_description/share/tracer_description/meshes/castor.dae"/>
      </geometry>
    </collision>
  </link>
  <joint name="fl_wheel" type="continuous">
    <!--<origin
                  xyz="0.14547 0.20835 -0.07424"
                  rpy="0 1.57 0" />-->
    <parent link="fl_castor_link"/>
    <child link="fl_wheel_link"/>
    <dynamics damping="0.0" friction="0.0"/>
    <origin rpy="0 0 0" xyz="-0.0218084 0.067 0"/>
    <axis rpy="0 0 0" xyz="0 0 1"/>
  </joint>
  <link name="fr_wheel_link">
    <inertial>
      <mass value="1"/>
      <origin xyz="0 0 0"/>
      <inertia ixx="0.3131" ixy="0" ixz="0" iyy="0.3131" iyz="0" izz="0.1361"/>
      <!--<inertia ixx="0" ixy="0" ixz="0" iyy="0" iyz="0" izz="0" />-->
    </inertial>
    <visual>
      <geometry>
        <!--<cylinder length="0.04653" radius="0.036"/>-->
        <!--<sphere radius="0.0457774"/>-->
        <mesh filename="file:///home/bing6866/桌面/work/松灵机器人/work1/重置版/ros2_ws/install/tracer_description/share/tracer_description/meshes/castor.dae"/>
      </geometry>
      <!--<material name="black">
                   <color rgba="255 255 255 1"/>
                   </material>-->
    </visual>
    <collision>
      <origin rpy="0 0 0" xyz="0 0 0"/>
      <geometry>
        <!--<cylinder length="0.04653" radius="0.036"/>-->
        <!--<cylinder length="0.0787019" radius="0.0457774"/>-->
        <!--<sphere radius="0.0457774"/>-->
        <mesh filename="file:///home/bing6866/桌面/work/松灵机器人/work1/重置版/ros2_ws/install/tracer_description/share/tracer_description/meshes/castor.dae"/>
      </geometry>
    </collision>
  </link>
  <joint name="fr_wheel" type="continuous">
    <!--<origin
                  xyz="0.14547 0.20835 -0.07424"
                  rpy="0 1.57 0" />-->
    <parent link="fr_castor_link"/>
    <child link="fr_wheel_link"/>
    <dynamics damping="0.0" friction="0.0"/>
    <origin rpy="0 0 0" xyz="-0.0218084 0.067 0"/>
    <axis rpy="0 0 0" xyz="0 0 1"/>
  </joint>
  <link name="rr_wheel_link">
    <inertial>
      <mass value="1"/>
      <origin xyz="0 0 0"/>
      <inertia ixx="0.3131" ixy="0" ixz="0" iyy="0.3131" iyz="0" izz="0.1361"/>
      <!--<inertia ixx="0" ixy="0" ixz="0" iyy="0" iyz="0" izz="0" />-->
    </inertial>
    <visual>
      <geometry>
        <!--<cylinder length="0.04653" radius="0.036"/>-->
        <!--<sphere radius="0.0457774"/>-->
        <mesh filename="file:///home/bing6866/桌面/work/松灵机器人/work1/重置版/ros2_ws/install/tracer_description/share/tracer_description/meshes/castor.dae"/>
      </geometry>
      <!--<material name="black">
                        <color rgba="255 255 255 1"/>
                   </material>-->
    </visual>
    <collision>
      <origin rpy="0 0 0" xyz="0 0 0"/>
      <geometry>
        <!--<mesh filename="file://$(find tracer_description)/meshes/wheel.dae" />-->
        <!--<cylinder length="0.04653" radius="0.036"/>-->
        <!-- <sphere radius="0.0457774"/>-->
        <mesh filename="file:///home/bing6866/桌面/work/松灵机器人/work1/重置版/ros2_ws/install/tracer_description/share/tracer_description/meshes/castor.dae"/>
      </geometry>
    </collision>
  </link>
  <joint name="rr_wheel" type="continuous">
    <!--<origin
                  xyz="0.14547 0.20835 -0.07424"
                  rpy="0 1.57 0" />-->
    <parent link="rr_castor_link"/>
    <child link="rr_wheel_link"/>
    <dynamics damping="0.0" friction="0.0"/>
    <origin rpy="0 0 0" xyz="-0.0218084 0.067 0"/>
    <axis rpy="0 0 0" xyz="0 0 1"/>
  </joint>
  <link name="rl_wheel_link">
    <inertial>
      <mass value="1"/>
      <origin xyz="0 0 0"/>
      <inertia ixx="0.3131" ixy="0" ixz="0" iyy="0.3131" iyz="0" izz="0.1361"/>
      <!--<inertia ixx="0" ixy="0" ixz="0" iyy="0" iyz="0" izz="0" />-->
    </inertial>
    <visual>
      <geometry>
        <!--<cylinder length="0.04653" radius="0.036"/>-->
        <!--<sphere radius="0.0457774"/>-->
        <mesh filename="file:///home/bing6866/桌面/work/松灵机器人/work1/重置版/ros2_ws/install/tracer_description/share/tracer_description/meshes/castor.dae"/>
      </geometry>
      <!--<material name="black">
                        <color rgba="255 255 255 1"/>
                   </material>-->
    </visual>
    <collision>
      <origin rpy="0 0 0" xyz="0 0 0"/>
      <geometry>
        <!--<cylinder length="0.04653" radius="0.036"/>-->
        <!--<cylinder length="0.0787019" radius="0.0457774"/>-->
        <!--<sphere radius="0.0457774"/>-->
        <mesh filename="file:///home/bing6866/桌面/work/松灵机器人/work1/重置版/ros2_ws/install/tracer_description/share/tracer_description/meshes/castor.dae"/>
      </geometry>
    </collision>
  </link>
  <joint name="rl_wheel" type="continuous">
    <!--<origin
                  xyz="0.14547 0.20835 -0.07424"
                  rpy="0 1.57 0" />-->
    <parent link="rl_castor_link"/>
    <child link="rl_wheel_link"/>
    <dynamics damping="0.0" friction="0.0"/>
    <origin rpy="0 0 0" xyz="-0.0218084 0.067 0"/>
    <axis rpy="0 0 0" xyz="0 0 1"/>
  </joint>
  <!-- Sensors -->
  <!-- <xacro:include filename="$(find tracer_description)/urdf/sensor/imu.urdf.xacro" />
    <xacro:include filename="$(find tracer_description)/urdf/sensor/camera.urdf.xacro" />
    <xacro:include filename="$(find tracer_description)/urdf/sensor/laser.urdf.xacro" /> -->
  <!-- 更合理的位置配置 -->
  <!-- <xacro:imu_xacro xyz="0.0 0.0 0.05" />         
    <xacro:camera_xacro xyz="0.25 0.0 0.12" />     
    <xacro:laser_xacro xyz="0.0 0.0 0.18" />        -->
  <!-- This file is a placeholder which is included by default from
       husky.urdf.xacro. If a robot is being customized and requires
       additional URDF, set the HUSKY_URDF_EXTRAS environment variable
       to the full path of the file you would like included. -->
  <!-- Additional definitions for simulation -->
  <!-- <gazebo reference="base_link">
        <material>Gazebo/Grey</material>
    </gazebo> -->
  <transmission name="right_wheel_trans" type="SimpleTransmission">
    <type>transmission_interface/SimpleTransmission</type>
    <actuator name="right_wheel_motor">
      <mechanicalReduction>1</mechanicalReduction>
    </actuator>
    <joint name="right_wheel">
      <hardwareInterface>hardware_interface/VelocityJointInterface</hardwareInterface>
    </joint>
  </transmission>
  <transmission name="left_wheel_trans" type="SimpleTransmission">
    <type>transmission_interface/SimpleTransmission</type>
    <actuator name="left_wheel_motor">
      <mechanicalReduction>1</mechanicalReduction>
    </actuator>
    <joint name="left_wheel">
      <hardwareInterface>hardware_interface/VelocityJointInterface</hardwareInterface>
    </joint>
  </transmission>
  <transmission name="fl_wheel_trans" type="SimpleTransmission">
    <type>transmission_interface/SimpleTransmission</type>
    <actuator name="fl_wheel_motor">
      <mechanicalReduction>1</mechanicalReduction>
    </actuator>
    <joint name="fl_wheel">
      <hardwareInterface>hardware_interface/VelocityJointInterface</hardwareInterface>
    </joint>
  </transmission>
  <transmission name="fr_wheel_trans" type="SimpleTransmission">
    <type>transmission_interface/SimpleTransmission</type>
    <actuator name="fr_wheel_motor">
      <mechanicalReduction>1</mechanicalReduction>
    </actuator>
    <joint name="fr_wheel">
      <hardwareInterface>hardware_interface/VelocityJointInterface</hardwareInterface>
    </joint>
  </transmission>
  <transmission name="rr_wheel_trans" type="SimpleTransmission">
    <type>transmission_interface/SimpleTransmission</type>
    <actuator name="rr_wheel_motor">
      <mechanicalReduction>1</mechanicalReduction>
    </actuator>
    <joint name="rr_wheel">
      <hardwareInterface>hardware_interface/VelocityJointInterface</hardwareInterface>
    </joint>
  </transmission>
  <transmission name="rl_wheel_trans" type="SimpleTransmission">
    <type>transmission_interface/SimpleTransmission</type>
    <actuator name="rl_wheel_motor">
      <mechanicalReduction>1</mechanicalReduction>
    </actuator>
    <joint name="rl_wheel">
      <hardwareInterface>hardware_interface/VelocityJointInterface</hardwareInterface>
    </joint>
  </transmission>
  <transmission name="fl_castor_wheel_trans" type="SimpleTransmission">
    <type>transmission_interface/SimpleTransmission</type>
    <actuator name="fl_castor_wheel_motor">
      <mechanicalReduction>1</mechanicalReduction>
    </actuator>
    <joint name="fl_castor_wheel">
      <hardwareInterface>hardware_interface/VelocityJointInterface</hardwareInterface>
    </joint>
  </transmission>
  <transmission name="fr_castor_wheel_trans" type="SimpleTransmission">
    <type>transmission_interface/SimpleTransmission</type>
    <actuator name="fr_castor_wheel_motor">
      <mechanicalReduction>1</mechanicalReduction>
    </actuator>
    <joint name="fr_castor_wheel">
      <hardwareInterface>hardware_interface/VelocityJointInterface</hardwareInterface>
    </joint>
  </transmission>
  <transmission name="rr_castor_wheel_trans" type="SimpleTransmission">
    <type>transmission_interface/SimpleTransmission</type>
    <actuator name="rr_castor_wheel_motor">
      <mechanicalReduction>1</mechanicalReduction>
    </actuator>
    <joint name="rr_castor_wheel">
      <hardwareInterface>hardware_interface/VelocityJointInterface</hardwareInterface>
    </joint>
  </transmission>
  <transmission name="rl_castor_wheel_trans" type="SimpleTransmission">
    <type>transmission_interface/SimpleTransmission</type>
    <actuator name="rl_castor_wheel_motor">
      <mechanicalReduction>1</mechanicalReduction>
    </actuator>
    <joint name="rl_castor_wheel">
      <hardwareInterface>hardware_interface/VelocityJointInterface</hardwareInterface>
    </joint>
  </transmission>
  <!-- Controller configurations -->
  <gazebo>
    <plugin filename="libgazebo_ros2_control.so" name="gazebo_ros2_control">
      <robotNamespace>/</robotNamespace>
    </plugin>
  </gazebo>
  <!-- kp spring constant, kd damping constant -->
  <gazebo>
    <mu1 value="1.0"/>
    <mu2 value="0.9"/>
    <kp value="10000000.0"/>
    <kd value="1.0"/>
    <fdir1 value="1 0 0"/>
    <minDepth value="0.001"/>
    <maxContacts value="64"/>
  </gazebo>
  <!-- <gazebo>
        <plugin name="skid_steer_drive_controller" filename="libgazebo_ros_skid_steer_drive.so">
            <updateRate>100.0</updateRate>
            <robotNamespace></robotNamespace>
            <leftFrontJoint>left_wheel</leftFrontJoint>
            <rightFrontJoint>right_wheel</rightFrontJoint>
            <wheelSeparation>2</wheelSeparation>
            <wheelDiameter>0.32918</wheelDiameter>
            <robotBaseFrame>base_link</robotBaseFrame>
            <torque>1000</torque>
            <commandTopic>cmd_vel</commandTopic>
            <broadcastTF>true</broadcastTF>
            <odometryTopic>odom</odometryTopic>
            <odometryFrame>odom</odometryFrame>
            <covariance_x>0.000100</covariance_x>
            <covariance_y>0.000100</covariance_y>
            <covariance_yaw>0.010000</covariance_yaw>
        </plugin>
    </gazebo> -->
  <gazebo>
    <plugin filename="libgazebo_ros_diff_drive.so" name="diff_drive">
      <ros>
        <namespace>/</namespace>
        <remapping>cmd_vel:=cmd_vel</remapping>
        <remapping>odom:=odom</remapping>
      </ros>
      <update_rate>30</update_rate>
      <left_joint>left_wheel</left_joint>
      <right_joint>right_wheel</right_joint>
      <wheel_separation>2</wheel_separation>
      <wheel_diameter>0.32918</wheel_diameter>
      <max_wheel_torque>1000</max_wheel_torque>
      <max_wheel_acceleration>1.0</max_wheel_acceleration>
      <publish_odom>true</publish_odom>
      <publish_odom_tf>true</publish_odom_tf>
      <publish_wheel_tf>true</publish_wheel_tf>
      <odometry_frame>odom</odometry_frame>
      <robot_base_frame>base_link</robot_base_frame>
    </plugin>
  </gazebo>
  <gazebo>
    <plugin filename="libgazebo_ros_trail_plugin.so" name="trail_plugin">
      <topicName>cmd_vel</topicName>
      <length>100</length>
      <radius>0.05</radius>
      <color>1 0 0 1</color>
    </plugin>
  </gazebo>
</robot>
